Workbook

Sheet Draft
A1: - | B1: - | C1: - | D1: - | E1: North India | O1: Central India | Q1: East India | U1: Northeast India | AC1: South India | AI1: West India
A2: S.no | B2: Date | C2: Festival | D2: Day | E2: Delhi | F2: Chandigarh | G2: Haryana | H2: Himachal Pradesh | I2: Jammu & Kashmir | J2: Ladakh | K2: Punjab | L2: Rajasthan | M2: Uttarakhand | N2: Uttar Pradesh | O2: Chhattisgarh | P2: Madhya Pradesh | Q2: Bihar | R2: Jharkhand | S2: Odisha | T2: West Bengal | U2: Arunachal Pradesh | V2: Assam | W2: Manipur | X2: Meghalaya | Y2: Mizoram | Z2: Nagaland | AA2: Sikkim | AB2: Tripura | AC2: Andhra Pradesh | AD2: Karnataka | AE2: Kerala | AF2: Puducherry | AG2: Tamil Nadu | AH2: Telangana | AI2: Goa | AJ2: Gujarat | AK2: Maharashtra | XDX2: Yes
A3: 1 | B3: 01-Jan-2026 | C3: New Year’s Day | D3: Thursday | E3: Yes | F3: Yes | G3: Yes | H3: Yes | I3: Yes | J3: Yes | K3: Yes | L3: Yes | M3: Yes | N3: Yes | O3: Yes | P3: Yes | Q3: Yes | R3: Yes | S3: Yes | T3: Yes | U3: Yes | V3: Yes | W3: Yes | X3: Yes | Y3: Yes | Z3: Yes | AA3: Yes | AB3: Yes | AC3: Yes | AD3: Yes | AE3: Yes | AF3: Yes | AG3: Yes | AH3: Yes | AI3: Yes | AJ3: Yes | AK3: Yes
A4: 2 | B4: 46024 | C4: Mannam Jayanthi | D4: Friday | AE4: Yes
A5: 3 | B5: 46028 | C5: Guru Gobind Singh Jayanti / Losar (Tibetan New Year) | D5: Tuesday | F5: Yes | J5: Yes
A6: 4 | B6: 46029 | C6: Naga Army Day | D6: Wednesday | Z6: Yes
A7: 5 | B7: 46034 | C7: Birthday of Swami Vivekananda | D7: Monday | T7: Yes
A8: 6 | B8: 46035 | C8: Lohri | D8: Tuesday | G8: Yes | K8: Yes
A9: 7 | B9: 14-Jan-2026 | C9: Pongal / Makar Sankranti/Magh Bihu & Tusu Puja | D9: Wednesday | G9: Yes | K9: Yes | R9: Yes | S9: Yes | U9: Yes | V9: Yes | AA9: Yes | AB9: Yes | AC9: Yes | AH9: Yes | AJ9: Yes
A10: 8 | B10: 46037 | C10: Uttarayana Punyakala, Makara Sankranti Festival/Pongal | D10: Thursday | AD10: Yes | AF10: Yes | AG10: Yes
A11: 9 | B11: 46038 | C11: Thiruvalluvar Day / Mattu Pongal / Kanuma (AP only) | D11: Friday | AC11: Yes | AF11: Yes | AG11: Yes
A12: 10 | B12: 46039 | C12: Uzhavar Thirunal | D12: Saturday | AG12: Yes
A13: 11 | B13: 46041 | C13: Sonam Lhosar / Sonam Lhochhar | D13: Monday | AA13: Yes
A14: 12 | B14: 46045 | C14: Basanta Panchami / Netaji Subhas Chandra Bose’s Birthday | D14: Friday | S14: Yes | T14: Yes | V14: Yes
A15: 13 | B15: 26-Jan-2026 | C15: Republic Day | D15: Monday | E15: Yes | F15: Yes | G15: Yes | H15: Yes | I15: Yes | J15: Yes | K15: Yes | L15: Yes | M15: Yes | N15: Yes | O15: Yes | P15: Yes | Q15: Yes | R15: Yes | S15: Yes | T15: Yes | U15: Yes | V15: Yes | W15: Yes | X15: Yes | Y15: Yes | Z15: Yes | AA15: Yes | AB15: Yes | AC15: Yes | AD15: MYES | AE15: MYES | AF15: MYES | AG15: MYES | AH15: MYES | AI15: MYES | AJ15: MYES | AK15: MYES
A16: 14 | B16: 46049 | C16: Gwthar Bathou San (Assam-specific) | D16: Tuesday | V16: Yes
A17: 15 | B17: 46051 | C17: Guru Gobind Singh Jayanti /Saraswati Puja | D17: Thursday | K17: Yes | N17: Yes | AB17: Yes
A18: 16 | B18: 46054 | C18: Thai Poosam | D18: Sunday | AG18: Yes
A19: 17 | B19: 46068 | C19: Mahasivarathri | D19: Sunday | F19: Yes | G19: Yes | H19: Yes | I19: Yes | J19: Yes | K19: Yes | L19: Yes | M19: Yes | N19: Yes | P19: Yes | AC19: Yes | AH19: Yes | AJ19: Yes | AK19: Yes
A20: 18 | B20: 46071 | C20: Losar (Tibetan New Year) | D20: Wednesday | AA20: Yes
A21: 19 | B21: 46072 | C21: Guru Rinpoche Day (commonly given in Leh) / Chhatrapati Shivaji Maharaj Jayanti | D21: Thursday | J21: Yes | AK21: Yes
A22: 20 | B22: 46073 | C22: State Day | D22: Friday | U22: Yes | Y22: Yes
A23: 21 | B23: 46084 | C23: Holi (Dhulivandana) / Doljatra (Holi festival) | D23: Tuesday | E23: Yes | I23: Yes | L23: Yes | M23: Yes | T23: Yes | V23: Yes | W23: Yes | AA23: Yes | AB23: Yes | AC23: Yes | AH23: Yes | AI23: Yes
A24: 22 | B24: 04-Mar-2026 | C24: Holi | D24: Wednesday | F24: Yes | G24: Yes | H24: Yes | J24: Yes | K24: Yes | L24: Yes | N24: Yes | O24: Yes | P24: Yes | Q24: Yes | R24: Yes | S24: Yes | U24: Yes | X24: Yes | Y24: Yes | Z24: Yes | AH24: Yes | AJ24: Yes | AK24: Yes
A25: 23 | B25: 46094 | C25: Chapchar Kut | D25: Friday | Y25: Yes
A26: 24 | B26: 46098 | C26: Shab-i-Qadr | D26: Tuesday | I26: Yes
A27: 25 | B27: 46100 | C27: Ugadi Festival / Telegu New Year /Gudi Padava / 904082 | D27: Thursday | AD27: Yes | AG27: Yes | AI27: Yes | AJ27: Yes | AK27: Yes
A28: 26 | B28: 46101 | C28: Id-ul-Fitr (Ramzan)* / Gudi Padwa / Ugadi (Telugu New Year) | D28: Friday | I28: Yes | L28: Yes | M28: Yes | P28: Yes | AC28: Yes | AE28: Yes | AF28: Yes
A29: 27 | B29: 21-Mar-2026 | C29: Id-ul-Fitr (Tentative) / Khutub-E-Ramzan | D29: Saturday | E29: Yes | F29: Yes | G29: Yes | H29: Yes | J29: Yes | K29: Yes | L29: Yes | N29: Yes | O29: Yes | P29: Yes | Q29: Yes | R29: Yes | S29: Yes | U29: Yes | V29: Yes | W29: Yes | X29: Yes | Y29: Yes | Z29: Yes | AC29: Yes | AD29: Yes | AG29: Yes | AH29: Yes | AI29: Yes | AJ29: Yes | AK29: Yes
A30: 28 | B30: 46103 | C30: Bihar Diwas | D30: Sunday | Q30: Yes
A31: 29 | B31: 26-Mar-2026 | C31: Ram Navami | D31: Thursday | E31: Yes | F31: Yes | G31: Yes | H31: Yes | I31: Yes | J31: Yes | K31: Yes | L31: Yes | M31: Yes | N31: Yes | P31: Yes | R31: Yes | T31: Yes | Y31: Yes | AA31: Yes | AC31: Yes | AH31: Yes | AI31: Yes | AK31: Yes
A32: 30 | B32: 46108 | C32: Shree Ram Navami | D32: Friday | Q32: Yes | S32: Yes | AJ32: Yes
A33: 31 | B33: 31-Mar-2026 | C33: Mahavir Jayanti | D33: Tuesday | E33: Yes | F33: Yes | G33: Yes | J33: Yes | K33: Yes | L33: Yes | M33: Yes | N33: Yes | O33: Yes | P33: Yes | Q33: Yes | R33: Yes | T33: Yes | Y33: Yes | AD33: Yes | AG33: Yes | AJ33: Yes | AK33: Yes
A34: 32 | B34: 46114 | C34: Maundy Thursday | D34: Thursday | AE34: Yes
A35: 33 | B35: 03-Apr-2026 | C35: Good Friday | D35: Friday | E35: Yes | F35: Yes | G35: Yes | H35: Yes | J35: Yes | K35: Yes | L35: Yes | M35: Yes | N35: Yes | O35: Yes | P35: Yes | Q35: Yes | R35: Yes | S35: Yes | T35: Yes | U35: Yes | V35: Yes | W35: Yes | X35: Yes | Y35: Yes | Z35: Yes | AA35: Yes | AB35: Yes | AC35: Yes | AD35: Yes | AE35: Yes | AF35: Yes | AG35: Yes | AH35: Yes | AI35: Yes | AJ35: Yes | AK35: Yes
A36: 34 | B36: 46117 | C36: Easter | D36: Sunday | AC36: Yes
A37: 35 | B37: 46126 | C37: Dr. B. R. Ambedkar Jayanthi / Tamil New Year / Maha Visuva Shankranti / Bohag Bihu (Assamese New Year) / Cheiraoba (Manipuri New Year)/Bengali New Year / Pohela Boishakh | D37: Tuesday | F37: Yes | G37: Yes | H37: Yes | I37: Yes | J37: Yes | K37: Yes | L37: Yes | M37: Yes | N37: Yes | P37: Yes | Q37: Yes | R37: Yes | S37: Yes | T37: Yes | V37: Yes | W37: Yes | AA37: Yes | AB37: Yes | AC37: Yes | AD37: Yes | AE37: Yes | AF37: Yes | AG37: Yes | AH37: Yes | AI37: Yes | AJ37: Yes | AK37: Yes
A38: 36 | B38: 46127 | C38: Vishu / Himachal Day / Bohag Bihu | D38: Wednesday | H38: Yes | U38: Yes | V38: Yes | AE38: Yes
A39: 37 | B39: 46128 | C39: Bohag Bihu - Day 3 | D39: Thursday | V39: Yes
A40: 38 | B40: 46132 | C40: Basava Jayanthi, Akshaya Tritiya | D40: Monday | AD40: Yes
...

Sheet New Sheet
A1: Sl.no. | B1: Date | C1: Festival | D1: Day | E1: North India | O1: Central India | Q1: East India | U1: Northeast India | AC1: South India | AI1: West India
E2: Delhi | F2: Chandigarh | G2: Haryana | H2: Himachal Pradesh | I2: Jammu & Kashmir | J2: Ladakh | K2: Punjab | L2: Rajasthan | M2: Uttarakhand | N2: Uttar Pradesh | O2: Chhattisgarh | P2: Madhya Pradesh | Q2: Bihar | R2: Jharkhand | S2: Odisha | T2: West Bengal | U2: Arunachal Pradesh | V2: Assam | W2: Manipur | X2: Meghalaya | Y2: Mizoram | Z2: Nagaland | AA2: Sikkim | AB2: Tripura | AC2: Andhra Pradesh | AD2: Karnataka | AE2: Kerala | AF2: Puducherry | AG2: Tamil Nadu | AH2: Telangana | AI2: Goa | AJ2: Gujarat | AK2: Maharashtra | XDX2: Yes
A3: 1 | B3: 46023 | C3: New Year’s Day | D3: Thursday | O3: Regional | Q3: Optional | S3: Optional | X3: Optional | Y3: Optional | AA3: Optional | AD3: Regional | AE3: Optional | AF3: Optional | AG3: Optional | AI3: Optional
A4: 2 | B4: 46024 | C4: Mannam Jayanthi | D4: Friday
B5: 46025 | C5: Maa Shakambhari Jayanti & Cherchera / Birthday of Hazarat Ali / Savitribai Phule Jayanti | D5: Saturday | O5: Regional-WE
A6: 3 | B6: 46028 | C6: Guru Gobind Singh Jayanti / Losar (Tibetan New Year) | D6: Tuesday
A7: 4 | B7: 46029 | C7: Naga Army Day /Rajim Bhaktin Mata Jayanti | D7: Wednesday | O7: Regional
B8: 46032 | C8: World Hindi Day | D8: Saturday | O8: Regional-WE
B9: 46033 | C9: Missionary Day | D9: Sunday
A10: 5 | B10: 46034 | C10: Birthday of Swami Vivekananda | D10: Monday
A11: 6 | B11: 46035 | C11: Lohri | D11: Tuesday
A12: 7 | B12: 46036 | C12: Pongal / Makar Sankranti/Magh Bihu & Tusu Puja | D12: Wednesday | O12: Regional | Q12: Regional | V12: Regional
A13: 8 | B13: 46037 | C13: Uttarayana Punyakala, Makara Sankranti Festival/Pongal | D13: Thursday | S13: Regional | V13: Regional | X13: Regional | Y13: Regional | AA13: Regional | AD13: Regional | AE13: Regional | AF13: Regional | AG13: Regional
A14: 9 | B14: 46038 | C14: Thiruvalluvar Day / Mattu Pongal / Kanuma (AP only) | D14: Friday | AE14: Regional | AF14: Regional | AG14: Regional
A15: 10 | B15: 46039 | C15: Uzhavar Thirunal | D15: Saturday | AE15: Regional-WE | AF15: Regional-WE | AG15: Regional-WE
A16: 11 | B16: 46041 | C16: Sonam Lhosar / Sonam Lhochhar | D16: Monday | S16: Optional | X16: Optional | Y16: Optional | AA16: Optional
B17: 46042 | C17: Shaheed Gaindsingh Shahadat Diwas | D17: Tuesday | O17: Regional
A18: 12 | B18: 46045 | C18: Basanta Panchami / Netaji Subhas Chandra Bose’s Birthday | D18: Friday | O18: Regional | Q18: Regional | V18: Regional
B19: 46046 | C19: Karpoori Thakur Jayanti | D19: Saturday | Q19: Regional-WE
B20: 46047 | C20: Deonarayan Jayanti | D20: Sunday | L20: Regional-WE
A21: 13 | B21: 46048 | C21: Republic Day | D21: Monday | L21: National | O21: National | Q21: National | S21: National | V21: National | X21: National | Y21: National | AA21: National | AD21: National | AE21: National | AF21: National | AG21: National | AI21: National
A22: 14 | B22: 46049 | C22: Gwthar Bathou San (Assam-specific)/Sri Madvanavami | D22: Tuesday | V22: Regional | AD22: Regional
A23: 15 | B23: 46051 | C23: Guru Gobind Singh Jayanti /Saraswati Puja | D23: Thursday
B24: 46053 | C24: Me-Dam-Me-Phi | D24: Saturday | V24: Regional-WE
A25: 16 | B25: 46054 | C25: Sant Ravidas Jayanthi | D25: Sunday | Q25: Regional-WE | V25: Regional-WE | AE25: Regional-WE | AF25: Regional-WE | AG25: Regional-WE
B26: 46056 | C26: Shab-e-Barat | D26: Tuesday | O26: Regional
B27: 46057 | C27: Shab-e-Barath | D27: Wednesday | Q27: Regional | AD27: Regional
B28: 46065 | C28: Maharshi Dayanand Saraswati Jayanti | D28: Thursday | O28: Regional
A29: 17 | B29: 46068 | C29: Mahasivarathri | D29: Sunday | L29: Regional-WE | S29: Regional-WE | AI29: Regional-WE
B30: 46069 | C30: Mahashivrathri | D30: Monday | Q30: Regional
A31: 18 | B31: 46071 | C31: Losar (Tibetan New Year) | D31: Wednesday | S31: Regional | X31: Regional | Y31: Regional | AA31: Regional
A32: 19 | B32: 46072 | C32: Guru Rinpoche Day (commonly given in Leh) / Chhatrapati Shivaji Maharaj Jayanti | D32: Thursday | O32: Regional
A33: 20 | B33: 46073 | C33: State Day | D33: Friday
B34: 46079 | C34: Akhil Sikkim Khas Chettri Bahun Kalyan Sangh's Foundation Day | D34: Thursday | S34: Regional | X34: Regional | Y34: Regional | AA34: Regional
B35: 46083 | C35: Holi ka dahan / Ramzan | D35: Monday | L35: Regional | Q35: Regional | AD35: Regional
A36: 21 | B36: 46084 | C36: Holi | D36: Tuesday | L36: Regional | O36: Regional | Q36: Regional | S36: Regional | V36: Regional | X36: Regional | Y36: Regional | AA36: Regional | AI36: Regional
A37: 22 | B37: 46085 | C37: Holi | D37: Wednesday | O37: Regional
B38: 46086 | C38: Bhai-Dooj (Holi) | D38: Thursday | O38: Regional
A39: 23 | B39: 46094 | C39: Chapchar Kut | D39: Friday
A40: 24 | B40: 46098 | C40: Shab-i-Qadr | D40: Tuesday | AD40: Regional
...

Sheet Sheet2
A1: National
A2: Regional
A3: Public
A4: Optional
A5: National-WE
A6: Regional-WE
A7: Public-WE
A8: Optional-WE

Sheet For Senior grades- 13 days
A1: Sl.no. | B1: Date | C1: Festival | D1: Day | E1: Delhi | F1: Chandigarh | G1: Haryana | H1: Himachal Pradesh | I1: Jammu & Kashmir | J1: Ladakh | K1: Punjab | L1: Rajasthan | M1: Uttarakhand | N1: Uttar Pradesh | O1: Chhattisgarh | P1: Madhya Pradesh | Q1: Bihar | R1: Jharkhand | S1: Odisha | T1: West Bengal | U1: Arunachal Pradesh | V1: Assam | W1: Manipur | X1: Meghalaya | Y1: Mizoram | Z1: Nagaland | AA1: Sikkim | AB1: Tripura | AC1: Andhra Pradesh | AD1: Karnataka | AE1: Kerala | AF1: Puducherry | AG1: Tamil Nadu | AH1: Telangana | AI1: Goa | AJ1: Gujarat | AK1: Maharashtra | XDX1: Yes
A2: 1 | B2: 46023 | C2: New Year’s Day | D2: Thursday | H2: Optional | N2: Regional | O2: Regional | Q2: Optional | T2: Regional | W2: Regional | X2: Optional | Y2: Optional | AA2: Optional | AD2: Regional | AE2: Optional | AF2: Regional | AG2: Optional | AI2: Optional | AJ2: =VLOOKUP(B2,'For A grades - 11 days'!B1:AJ187,35,0) -> Optional
A3: 2 | B3: 46024 | C3: Mannam Jayanthi | D3: Friday | Y3: Regional
A4: 3 | B4: 46025 | C4: Maa Shakambhari Jayanti & Cherchera / Birthday of Hazarat Ali / Savitribai Phule Jayanti | D4: Saturday | J4: Optional-WE | N4: Regional-WE | O4: Regional-WE
A5: 4 | B5: 46027 | C5: Guru Gobind Singh Jayanti / Losar (Tibetan New Year) | D5: Tuesday | J5: Optional | N5: Regional
A6: 5 | B6: 46029 | C6: Naga Army Day /Rajim Bhaktin Mata Jayanti | D6: Wednesday | O6: Regional
B7: 46031 | C7: Death Anniversary of (L) Maharaja Gambhir Singh | D7: Friday | W7: Regional
A8: 6 | B8: 46032 | C8: World Hindi Day | D8: Saturday | O8: Regional-WE
A9: 7 | B9: 46033 | C9: Missionary Day | D9: Sunday | Y9: Optional-WE
A10: 8 | B10: 46034 | C10: Birthday of Swami Vivekananda | D10: Monday | T10: Regional
A11: 9 | B11: 46035 | C11: Lohri | D11: Tuesday | J11: Optional
A12: 10 | B12: 46036 | C12: Pongal / Makar Sankranti/Magh Bihu & Tusu Puja | D12: Wednesday | H12: Optional | N12: Regional | O12: Regional | Q12: Regional | S12: Regional | V12: Regional | AJ12: =VLOOKUP(B12,'For A grades - 11 days'!B11:AJ200,35,0) -> Regional
A13: 11 | B13: 46037 | C13: Uttarayana Punyakala, Makara Sankranti Festival/Pongal | D13: Thursday | V13: Regional | AA13: Regional | AD13: Regional | AE13: Regional | AF13: Regional | AG13: Regional | AJ13: =VLOOKUP(B13,'For A grades - 11 days'!B12:AJ201,35,0) -> Optional
A14: 12 | B14: 46038 | C14: Thiruvalluvar Day / Mattu Pongal / Kanuma (AP only) | D14: Friday | AE14: Regional | AF14: Regional | AG14: Regional
A15: 13 | B15: 46039 | C15: Uzhavar Thirunal | D15: Saturday | J15: Optional-WE | AE15: Regional-WE | AG15: Regional-WE
A16: 14 | B16: 46041 | C16: Sonam Lhosar / Sonam Lhochhar | D16: Monday | AA16: Optional
A17: 15 | B17: 46042 | C17: Shaheed Gaindsingh Shahadat Diwas | D17: Tuesday | O17: Regional
A18: 16 | B18: 46045 | C18: Basanta Panchami / Netaji Subhas Chandra Bose’s Birthday | D18: Friday | H18: Optional | N18: Regional | O18: Regional | Q18: Regional | S18: Regional | T18: Regional | V18: Regional
A19: 17 | B19: 46046 | C19: Karpoori Thakur Jayanti | D19: Saturday | N19: Regional-WE | Q19: Regional-WE
A20: 18 | B20: 46047 | C20: Deonarayan Jayanti / Statehood Day | D20: Sunday | H20: Regional-WE | L20: Regional-WE
A21: 19 | B21: 46048 | C21: Republic Day | D21: Monday | H21: National | J21: National | L21: National | N21: National | O21: National | Q21: National | S21: National | T21: National | V21: National | W21: National | X21: National | Y21: National | AA21: National | AD21: National | AE21: National | AF21: National | AG21: National | AI21: National | AJ21: =VLOOKUP(B21,'For A grades - 11 days'!B20:AJ209,35,0) -> National
A22: 20 | B22: 46049 | C22: Gwthar Bathou San (Assam-specific)/Sri Madvanavami | D22: Tuesday | V22: Regional | AD22: Regional
A23: 21 | B23: 46051 | C23: Guru Gobind Singh Jayanti /Saraswati Puja | D23: Thursday
A24: 22 | B24: 46053 | C24: Me-Dam-Me-Phi | D24: Saturday | V24: Regional-WE | AJ24: =VLOOKUP(B24,'For A grades - 11 days'!B23:AJ212,35,0) -> Optional-WE
A25: 23 | B25: 46054 | C25: Sant Ravidas Jayanthi | D25: Sunday | H25: Regional-WE | N25: Regional-WE | Q25: Regional-WE | V25: Regional-WE | AE25: Regional-WE | AG25: Regional-WE
A26: 24 | B26: 46056 | C26: Shab-e-Barat | D26: Tuesday | O26: Regional
A27: 25 | B27: 46057 | C27: Shab-e-Barath | D27: Wednesday | N27: Regional | Q27: Regional | AD27: Regional | AJ27: =VLOOKUP(B27,'For A grades - 11 days'!B26:AJ215,35,0) -> Optional
A28: 26 | B28: 46065 | C28: Maharshi Dayanand Saraswati Jayanti | D28: Thursday | H28: Optional | O28: Regional
A29: 27 | B29: 46068 | C29: Mahasivarathri | D29: Sunday | H29: Regional-WE | J29: Optional-WE | L29: Regional-WE | N29: Regional-WE | S29: Regional-WE | T29: Regional-WE | W29: Regional-WE | AI29: Regional-WE | AJ29: =VLOOKUP(B29,'For A grades - 11 days'!B28:AJ217,35,0) -> Regional-WE
A30: 28 | B30: 46069 | C30: Mahashivrathri / Mela Dosmoche | D30: Monday | J30: Optional | Q30: Regional
A31: 29 | B31: 46071 | C31: Losar (Tibetan New Year) | D31: Wednesday | AA31: Regional
A32: 30 | B32: 46072 | C32: Guru Rinpoche Day (commonly given in Leh) / Chhatrapati Shivaji Maharaj Jayanti | D32: Thursday | O32: Regional
A33: 31 | B33: 46073 | C33: State Day | D33: Friday | Y33: Regional
A34: 32 | B34: 46079 | C34: Akhil Sikkim Khas Chettri Bahun Kalyan Sangh's Foundation Day | D34: Thursday | AA34: Regional
A35: 33 | B35: 46083 | C35: Holi ka dahan / Ramzan | D35: Monday | L35: Regional | N35: Regional | Q35: Regional | AD35: Regional
A36: 34 | B36: 46084 | C36: Holi / Tangpe Chongya | D36: Tuesday | J36: Optional | L36: Regional | O36: Regional | Q36: Regional | T36: Regional | V36: Regional | W36: Regional | AA36: Regional | AI36: Regional | AJ36: =VLOOKUP(B36,'For A grades - 11 days'!B35:AJ224,35,0) -> Optional
A37: 35 | B37: 46085 | C37: Holi | D37: Wednesday | H37: Regional | J37: Regional | N37: Regional | O37: Regional | S37: Regional | W37: Regional | X37: Regional | Y37: Regional | AJ37: =VLOOKUP(B37,'For A grades - 11 days'!B36:AJ225,35,0) -> Regional
A38: 36 | B38: 46086 | C38: Bhai-Dooj (Holi) | D38: Thursday | N38: Regional | O38: Regional
A39: 37 | B39: 46092 | C39: Sahahdat-e- hazrat Ali | D39: Wednesday | AJ39: =VLOOKUP(B39,'For A grades - 11 days'!B38:AJ227,35,0) -> Optional
A40: 38 | B40: 46094 | C40: Chapchar Kut | D40: Friday | J40: Optional | N40: Regional | Y40: Regional
...

Sheet For A grades - 11 days
A1: Sl.no. | B1: Date | C1: Festival | D1: Day | E1: Delhi | F1: Chandigarh | G1: Haryana | H1: Himachal Pradesh | I1: Jammu & Kashmir | J1: Ladakh | K1: Punjab | L1: Rajasthan | M1: Uttarakhand | N1: Uttar Pradesh | O1: Chhattisgarh | P1: Madhya Pradesh | Q1: Bihar | R1: Jharkhand | S1: Odisha | T1: West Bengal | U1: Arunachal Pradesh | V1: Assam | W1: Manipur | X1: Meghalaya | Y1: Mizoram | Z1: Nagaland | AA1: Sikkim | AB1: Tripura | AC1: Andhra Pradesh | AD1: Karnataka | AE1: Kerala | AF1: Puducherry | AG1: Tamil Nadu | AH1: Telangana | AI1: Goa | AJ1: Gujarat | AK1: Maharashtra | XDX1: Yes
A2: 1 | B2: 46023 | C2: New Year’s Day | D2: Thursday | H2: =VLOOKUP(B2,'For Senior grades- 13 days'!B1:H186,7,0) -> Optional | N2: =VLOOKUP(B2,'For Senior grades- 13 days'!B1:N186,13,0) -> Regional | O2: Regional | Q2: Optional | T2: Regional | W2: =VLOOKUP(B2,'For Senior grades- 13 days'!B1:W186,22,0) -> Regional | X2: Optional | Y2: Optional | AA2: Optional | AD2: Regional | AE2: Optional | AF2: Regional | AG2: Optional | AI2: Optional | AJ2: Optional
A3: 2 | B3: 46024 | C3: Mannam Jayanthi | D3: Friday | Y3: Regional
A4: 3 | B4: 46025 | C4: Maa Shakambhari Jayanti & Cherchera / Birthday of Hazarat Ali / Savitribai Phule Jayanti | D4: Saturday | J4: =VLOOKUP(B4,'For Senior grades- 13 days'!B3:J188,9,0) -> Optional-WE | N4: =VLOOKUP(B4,'For Senior grades- 13 days'!B3:N188,13,0) -> Regional-WE | O4: Regional-WE
A5: 4 | B5: 46027 | C5: Guru Gobind Singh Jayanti / Losar (Tibetan New Year) | D5: Tuesday | J5: =VLOOKUP(B5,'For Senior grades- 13 days'!B4:J189,9,0) -> Optional | N5: =VLOOKUP(B5,'For Senior grades- 13 days'!B4:N189,13,0) -> Regional
A6: 5 | B6: 46029 | C6: Naga Army Day /Rajim Bhaktin Mata Jayanti | D6: Wednesday | O6: Regional
B7: 46031 | C7: Death Anniversary of (L) Maharaja Gambhir Singh | D7: Friday | W7: =VLOOKUP(B7,'For Senior grades- 13 days'!B6:W191,22,0) -> Regional
A8: 6 | B8: 46032 | C8: World Hindi Day | D8: Saturday | O8: Regional-WE
A9: 7 | B9: 46033 | C9: Missionary Day | D9: Sunday | Y9: Optional-WE
A10: 8 | B10: 46034 | C10: Birthday of Swami Vivekananda | D10: Monday | T10: =VLOOKUP(B10,'For Senior grades- 13 days'!B9:T193,19,0) -> Regional
A11: 9 | B11: 46035 | C11: Lohri | D11: Tuesday | J11: =VLOOKUP(B11,'For Senior grades- 13 days'!B10:J194,9,0) -> Optional
A12: 10 | B12: 46036 | C12: Pongal / Makar Sankranti/Magh Bihu & Tusu Puja | D12: Wednesday | H12: =VLOOKUP(B12,'For Senior grades- 13 days'!B11:H195,7,0) -> Optional | N12: =VLOOKUP(B12,'For Senior grades- 13 days'!B11:N196,13,0) -> Regional | O12: Regional | Q12: Regional | S12: Regional | V12: Regional | AJ12: Regional
A13: 11 | B13: 46037 | C13: Uttarayana Punyakala, Makara Sankranti Festival/Pongal | D13: Thursday | V13: Regional | AA13: Regional | AD13: Regional | AE13: Regional | AF13: Regional | AG13: Regional | AJ13: Optional
A14: 12 | B14: 46038 | C14: Thiruvalluvar Day / Mattu Pongal / Kanuma (AP only) | D14: Friday | AE14: Regional | AF14: Regional | AG14: Regional
A15: 13 | B15: 46039 | C15: Uzhavar Thirunal | D15: Saturday | J15: =VLOOKUP(B15,'For Senior grades- 13 days'!B14:J198,9,0) -> Optional-WE | AE15: Regional-WE | AG15: Regional-WE
A16: 14 | B16: 46041 | C16: Sonam Lhosar / Sonam Lhochhar | D16: Monday | AA16: Optional
A17: 15 | B17: 46042 | C17: Shaheed Gaindsingh Shahadat Diwas | D17: Tuesday | O17: Regional
A18: 16 | B18: 46045 | C18: Basanta Panchami / Netaji Subhas Chandra Bose’s Birthday | D18: Friday | H18: =VLOOKUP(B18,'For Senior grades- 13 days'!B17:H201,7,0) -> Optional | N18: =VLOOKUP(B18,'For Senior grades- 13 days'!B17:N202,13,0) -> Regional | O18: Regional | Q18: Regional | S18: Regional | T18: =VLOOKUP(B18,'For Senior grades- 13 days'!B17:T201,19,0) -> Regional | V18: Regional
A19: 17 | B19: 46046 | C19: Karpoori Thakur Jayanti | D19: Saturday | N19: =VLOOKUP(B19,'For Senior grades- 13 days'!B18:N203,13,0) -> Regional-WE | Q19: Regional-WE
A20: 18 | B20: 46047 | C20: Deonarayan Jayanti | D20: Sunday | H20: =VLOOKUP(B20,'For Senior grades- 13 days'!B19:H203,7,0) -> Regional-WE | L20: Regional-WE
A21: 19 | B21: 46048 | C21: Republic Day | D21: Monday | H21: =VLOOKUP(B21,'For Senior grades- 13 days'!B20:H204,7,0) -> National | J21: =VLOOKUP(B21,'For Senior grades- 13 days'!B20:J204,9,0) -> National | L21: National | N21: =VLOOKUP(B21,'For Senior grades- 13 days'!B20:N205,13,0) -> National | O21: National | Q21: National | S21: National | T21: National | V21: National | W21: =VLOOKUP(B21,'For Senior grades- 13 days'!B20:W205,22,0) -> National | X21: National | Y21: National | AA21: National | AD21: National | AE21: National | AF21: National | AG21: National | AI21: National | AJ21: National
A22: 20 | B22: 46049 | C22: Gwthar Bathou San (Assam-specific)/Sri Madvanavami | D22: Tuesday | V22: Regional | AD22: Regional
A23: 21 | B23: 46051 | C23: Guru Gobind Singh Jayanti /Saraswati Puja | D23: Thursday
A24: 22 | B24: 46053 | C24: Me-Dam-Me-Phi / Vishwakarma Jayanti | D24: Saturday | V24: Regional-WE | AJ24: Optional-WE
A25: 23 | B25: 46054 | C25: Sant Ravidas Jayanthi | D25: Sunday | H25: =VLOOKUP(B25,'For Senior grades- 13 days'!B24:H208,7,0) -> Regional-WE | N25: =VLOOKUP(B25,'For Senior grades- 13 days'!B24:N209,13,0) -> Regional-WE | Q25: Regional-WE | V25: Regional-WE | AE25: Regional-WE | AG25: Regional-WE
A26: 24 | B26: 46056 | C26: Shab-e-Barat | D26: Tuesday | O26: Regional
A27: 25 | B27: 46057 | C27: Shab-e-Barath | D27: Wednesday | N27: =VLOOKUP(B27,'For Senior grades- 13 days'!B26:N211,13,0) -> Regional | Q27: Regional | AD27: Regional | AJ27: Optional
A28: 26 | B28: 46065 | C28: Maharshi Dayanand Saraswati Jayanti | D28: Thursday | H28: =VLOOKUP(B28,'For Senior grades- 13 days'!B27:H211,7,0) -> Optional | O28: Regional
A29: 27 | B29: 46068 | C29: Mahasivarathri | D29: Sunday | H29: =VLOOKUP(B29,'For Senior grades- 13 days'!B28:H212,7,0) -> Regional-WE | J29: =VLOOKUP(B29,'For Senior grades- 13 days'!B28:J212,9,0) -> Optional-WE | L29: Regional-WE | N29: =VLOOKUP(B29,'For Senior grades- 13 days'!B28:N213,13,0) -> Regional-WE | S29: Regional-WE | T29: =VLOOKUP(B29,'For Senior grades- 13 days'!B28:T212,19,0) -> Regional-WE | W29: =VLOOKUP(B29,'For Senior grades- 13 days'!B28:W213,22,0) -> Regional-WE | AI29: Regional-WE | AJ29: Regional-WE
A30: 28 | B30: 46069 | C30: Mahashivrathri / Mela Dosmoche | D30: Monday | J30: =VLOOKUP(B30,'For Senior grades- 13 days'!B29:J213,9,0) -> Optional | Q30: Regional
A31: 29 | B31: 46071 | C31: Losar (Tibetan New Year) | D31: Wednesday | AA31: Regional
A32: 30 | B32: 46072 | C32: Guru Rinpoche Day (commonly given in Leh) / Chhatrapati Shivaji Maharaj Jayanti | D32: Thursday | O32: Regional
A33: 31 | B33: 46073 | C33: State Day | D33: Friday | Y33: Regional
A34: 32 | B34: 46079 | C34: Akhil Sikkim Khas Chettri Bahun Kalyan Sangh's Foundation Day | D34: Thursday | AA34: Regional
A35: 33 | B35: 46083 | C35: Holi ka dahan / Ramzan | D35: Monday | L35: Regional | N35: =VLOOKUP(B35,'For Senior grades- 13 days'!B34:N219,13,0) -> Regional | Q35: Regional | AD35: Regional
A36: 34 | B36: 46084 | C36: Holi / Tangpe Chongya | D36: Tuesday | J36: =VLOOKUP(B36,'For Senior grades- 13 days'!B35:J219,9,0) -> Optional | L36: Regional | O36: Regional | Q36: Regional | T36: Regional | V36: Regional | W36: =VLOOKUP(B36,'For Senior grades- 13 days'!B35:W220,22,0) -> Regional | AA36: Regional | AI36: Regional | AJ36: Optional
A37: 35 | B37: 46085 | C37: Holi | D37: Wednesday | H37: =VLOOKUP(B37,'For Senior grades- 13 days'!B36:H220,7,0) -> Regional | J37: =VLOOKUP(B37,'For Senior grades- 13 days'!B36:J220,9,0) -> Regional | N37: =VLOOKUP(B37,'For Senior grades- 13 days'!B36:N221,13,0) -> Regional | O37: Regional | S37: Regional | W37: =VLOOKUP(B37,'For Senior grades- 13 days'!B36:W221,22,0) -> Regional | X37: Regional | Y37: Regional | AJ37: Regional
A38: 36 | B38: 46086 | C38: Bhai-Dooj (Holi) | D38: Thursday | N38: =VLOOKUP(B38,'For Senior grades- 13 days'!B37:N222,13,0) -> Regional | O38: Regional
A39: 37 | B39: 46092 | C39: Sahahdat-e- hazrat Ali | D39: Wednesday | AJ39: Optional
A40: 38 | B40: 46094 | C40: Chapchar Kut | D40: Friday | J40: =VLOOKUP(B40,'For Senior grades- 13 days'!B39:J223,9,0) -> Optional | N40: =VLOOKUP(B40,'For Senior grades- 13 days'!B39:N224,13,0) -> Regional | Y40: Regional
...

Sheet All ecxept A grades - 13 days
A1: Sl.no. | B1: Date | C1: Festival | D1: Day | E1: Delhi | F1: Chandigarh | G1: Haryana | H1: Himachal Pradesh | I1: Jammu & Kashmir | J1: Ladakh | K1: Punjab | L1: Rajasthan | M1: Uttarakhand | N1: Uttar Pradesh | O1: Chhattisgarh | P1: Madhya Pradesh | Q1: Bihar | R1: Jharkhand | S1: Odisha | T1: West Bengal | U1: Arunachal Pradesh | V1: Assam | W1: Manipur | X1: Meghalaya | Y1: Mizoram | Z1: Nagaland | AA1: Sikkim | AB1: Tripura | AC1: Andhra Pradesh | AD1: Karnataka | AE1: Kerala | AF1: Puducherry | AG1: Tamil Nadu | AH1: Telangana | AI1: Goa | AJ1: Gujarat | AK1: Maharashtra | XDX1: Yes
A2: 1 | B2: 46023 | C2: New Year’s Day | D2: Thursday | E2: Digi_Festival | F2: Digi_Festival | G2: Digi_Festival | H2: Digi_Festival | I2: Digi_Festival | K2: Digi_Festival | M2: Digi_Festival | N2: Digi_Festival | O2: Digi_Festival | P2: Digi_Festival | Q2: Digi_Festival | R2: Digi_Festival | S2: Digi_Festival | T2: Digi_Festival | U2: Digi_Festival | W2: Digi_Festival | X2: Digi_Festival | Y2: Digi_Festival | Z2: Digi_Festival | AA2: Digi_Festival | AB2: Digi_Festival | AC2: Digi_Festival | AD2: Digi_Festival | AE2: Digi_Festival | AF2: Digi_Festival | AG2: Digi_Festival | AH2: Digi_Festival | AI2: Digi_Festival | AJ2: Digi_Festival | AK2: Digi_Festival
A3: 2 | B3: 46024 | C3: Mannam Jayanthi | D3: Friday
A4: 3 | B4: 46025 | C4: Maa Shakambhari Jayanti & Cherchera / Birthday of Hazarat Ali / Savitribai Phule Jayanti | D4: Saturday
A5: 4 | B5: 46027 | C5: Guru Gobind Singh Jayanti / Losar (Tibetan New Year) | D5: Tuesday | J5: Digi_Festival
A6: 5 | B6: 46029 | C6: Naga Army Day /Rajim Bhaktin Mata Jayanti | D6: Wednesday
A7: 6 | B7: 46031 | C7: Death Anniversary of (L) Maharaja Gambhir Singh | D7: Friday
A8: 7 | B8: 46032 | C8: World Hindi Day | D8: Saturday
A9: 8 | B9: 46033 | C9: Missionary Day | D9: Sunday
A10: 9 | B10: 46034 | C10: Birthday of Swami Vivekananda | D10: Monday
A11: 10 | B11: 46035 | C11: Lohri | D11: Tuesday | G11: Digi_Festival | I11: Digi_Festival | K11: Digi_Festival
A12: 11 | B12: 46036 | C12: Pongal / Makar Sankranti/Magh Bihu & Tusu Puja | D12: Wednesday | F12: Digi_Festival | M12: Digi_Festival | O12: Digi_Festival | P12: Digi_Festival | Q12: Digi_Festival | R12: Digi_Festival | Z12: Digi_Festival | AB12: Digi_Festival | AC12: Digi_Festival | AJ12: Digi_Festival
A13: 12 | B13: 46037 | C13: Uttarayana Punyakala, Makara Sankranti Festival/Pongal | D13: Thursday | AA13: Digi_Festival | AC13: Digi_Festival | AD13: Digi_Festival | AE13: Digi_Festival | AG13: Digi_Festival | AH13: Digi_Festival
A14: 13 | B14: 46038 | C14: Thiruvalluvar Day / Mattu Pongal / Kanuma (AP only) | D14: Friday | AC14: Digi_Festival | AE14: Digi_Festival | AF14: Digi_Festival | AG14: Digi_Festival
A15: 14 | B15: 46039 | C15: Uzhavar Thirunal | D15: Saturday
A16: 15 | B16: 46041 | C16: Sonam Lhosar / Sonam Lhochhar | D16: Monday
A17: 16 | B17: 46042 | C17: Shaheed Gaindsingh Shahadat Diwas | D17: Tuesday
A18: 17 | B18: 46045 | C18: Basanta Panchami / Netaji Subhas Chandra Bose’s Birthday | D18: Friday
A19: 18 | B19: 46046 | C19: Karpoori Thakur Jayanti | D19: Saturday
A20: 19 | B20: 46047 | C20: Deonarayan Jayanti | D20: Sunday
A21: 20 | B21: 46048 | C21: Republic Day | D21: Monday | E21: Digi_National | F21: Digi_National | G21: Digi_National | H21: Digi_National | I21: Digi_National | J21: Digi_National | K21: Digi_National | L21: Digi_National | M21: Digi_National | N21: Digi_National | O21: Digi_National | P21: Digi_National | Q21: Digi_National | R21: Digi_National | S21: Digi_National | T21: Digi_National | U21: Digi_National | V21: Digi_National | W21: Digi_National | X21: Digi_National | Y21: Digi_National | Z21: Digi_National | AA21: Digi_National | AB21: Digi_National | AC21: Digi_National | AD21: Digi_National | AE21: Digi_National | AF21: Digi_National | AG21: Digi_National | AH21: Digi_National | AI21: Digi_National | AJ21: Digi_National | AK21: Digi_National
A22: 21 | B22: 46049 | C22: Gwthar Bathou San (Assam-specific)/Sri Madvanavami | D22: Tuesday | V22: Digi_Festival
A23: 22 | B23: 46051 | C23: Guru Gobind Singh Jayanti /Saraswati Puja | D23: Thursday
A24: 23 | B24: 46053 | C24: Me-Dam-Me-Phi / Vishwakarma Jayanti | D24: Saturday
A25: 24 | B25: 46054 | C25: Sant Ravidas Jayanthi | D25: Sunday
A26: 25 | B26: 46056 | C26: Shab-e-Barat | D26: Tuesday
A27: 26 | B27: 46057 | C27: Shab-e-Barath | D27: Wednesday
A28: 27 | B28: 46065 | C28: Maharshi Dayanand Saraswati Jayanti | D28: Thursday
A29: 28 | B29: 46068 | C29: Mahasivarathri | D29: Sunday
A30: 29 | B30: 46069 | C30: Mahashivrathri / Mela Dosmoche | D30: Monday
A31: 30 | B31: 46071 | C31: Losar (Tibetan New Year) | D31: Wednesday | AA31: Digi_Festival
A32: 31 | B32: 46072 | C32: Guru Rinpoche Day (commonly given in Leh) / Chhatrapati Shivaji Maharaj Jayanti | D32: Thursday
A33: 32 | B33: 46073 | C33: State Day | D33: Friday | U33: Digi_National | Y33: Digi_Festival
A34: 33 | B34: 46079 | C34: Akhil Sikkim Khas Chettri Bahun Kalyan Sangh's Foundation Day | D34: Thursday | AA34: Digi_Festival
A35: 34 | B35: 46083 | C35: Holi ka dahan / Ramzan | D35: Monday | L35: Digi_Festival
A36: 35 | B36: 46084 | C36: Holi / Tangpe Chongya | D36: Tuesday | L36: Digi_Festival | Q36: Digi_Festival | T36: Digi_Festival | V36: Digi_Festival | W36: Digi_Festival | AA36: Digi_Festival | AC36: Digi_Festival | AH36: Digi_Festival | AI36: Digi_Festival
A37: 36 | B37: 46085 | C37: Holi | D37: Wednesday | E37: Digi_Festival | F37: Digi_Festival | G37: Digi_Festival | H37: Digi_Festival | I37: Digi_Festival | K37: Digi_Festival | M37: Digi_Festival | N37: Digi_Festival | O37: Digi_Festival | P37: Digi_Festival | R37: Digi_Festival | S37: Digi_Festival | U37: Digi_Festival | X37: Digi_Festival | Y37: Digi_Festival | Z37: Digi_Festival | AB37: Digi_Festival | AJ37: Digi_Festival | AK37: Digi_Festival
A38: 37 | B38: 46086 | C38: Bhai-Dooj (Holi) | D38: Thursday
A39: 38 | B39: 46091 | C39: Shahadat Hzt Ali (R.A.) | D39: Tuesday
A40: 39 | B40: 46092 | C40: Sahahdat-e- hazrat Ali | D40: Wednesday
...

Sheet A Grades - 11 days
A1: Sl.no. | B1: Date | C1: Festival | D1: Day | E1: Delhi | F1: Chandigarh | G1: Haryana | H1: Himachal Pradesh | I1: Jammu & Kashmir | J1: Ladakh | K1: Punjab | L1: Rajasthan | M1: Uttarakhand | N1: Uttar Pradesh | O1: Chhattisgarh | P1: Madhya Pradesh | Q1: Bihar | R1: Jharkhand | S1: Odisha | T1: West Bengal | U1: Arunachal Pradesh | V1: Assam | W1: Manipur | X1: Meghalaya | Y1: Mizoram | Z1: Nagaland | AA1: Sikkim | AB1: Tripura | AC1: Andhra Pradesh | AD1: Karnataka | AE1: Kerala | AF1: Puducherry | AG1: Tamil Nadu | AH1: Telangana | AI1: Goa | AJ1: Gujarat | AK1: Maharashtra | XDX1: Yes
A2: 1 | B2: 46023 | C2: New Year’s Day | D2: Thursday | G2: Digi_Festival | I2: Digi_Festival | K2: Digi_Festival | M2: Digi_Festival | N2: Digi_Festival | P2: Digi_Festival | U2: Digi_Festival | Z2: Digi_Festival | AD2: Digi_Festival | AG2: Digi_Festival | AH2: Digi_Festival | AI2: Digi_Festival | AK2: Digi_Festival
A3: 2 | B3: 46024 | C3: Mannam Jayanthi | D3: Friday
A4: 3 | B4: 46025 | C4: Maa Shakambhari Jayanti & Cherchera / Birthday of Hazarat Ali / Savitribai Phule Jayanti | D4: Saturday
A5: 4 | B5: 46027 | C5: Guru Gobind Singh Jayanti / Losar (Tibetan New Year) | D5: Tuesday
A6: 5 | B6: 46029 | C6: Naga Army Day /Rajim Bhaktin Mata Jayanti | D6: Wednesday
A7: 6 | B7: 46031 | C7: Death Anniversary of (L) Maharaja Gambhir Singh | D7: Friday
A8: 7 | B8: 46032 | C8: World Hindi Day | D8: Saturday
A9: 8 | B9: 46033 | C9: Missionary Day | D9: Sunday
A10: 9 | B10: 46034 | C10: Birthday of Swami Vivekananda | D10: Monday
A11: 10 | B11: 46035 | C11: Lohri | D11: Tuesday | G11: Digi_Festival
A12: 11 | B12: 46036 | C12: Pongal / Makar Sankranti/Magh Bihu & Tusu Puja | D12: Wednesday | F12: =VLOOKUP(C12,'All ecxept A grades - 13 days'!C11:F205,4,0) -> Digi_Festival | O12: Digi_Festival | Q12: Digi_Festival | R12: Digi_Festival | Z12: Digi_Festival | AB12: Digi_Festival | AJ12: Digi_Festival
A13: 12 | B13: 46037 | C13: Uttarayana Punyakala, Makara Sankranti Festival/Pongal | D13: Thursday | AA13: Digi_Festival | AC13: =VLOOKUP(B12,'All ecxept A grades - 13 days'!B11:AC205,28,0) -> Digi_Festival | AD13: Digi_Festival | AE13: Digi_Festival | AG13: Digi_Festival | AH13: Digi_Festival
A14: 13 | B14: 46038 | C14: Thiruvalluvar Day / Mattu Pongal / Kanuma (AP only) | D14: Friday | AE14: Digi_Festival | AF14: Digi_Festival | AG14: Digi_Festival
A15: 14 | B15: 46039 | C15: Uzhavar Thirunal | D15: Saturday
A16: 15 | B16: 46041 | C16: Sonam Lhosar / Sonam Lhochhar | D16: Monday
A17: 16 | B17: 46042 | C17: Shaheed Gaindsingh Shahadat Diwas | D17: Tuesday
A18: 17 | B18: 46045 | C18: Basanta Panchami / Netaji Subhas Chandra Bose’s Birthday | D18: Friday
A19: 18 | B19: 46046 | C19: Karpoori Thakur Jayanti | D19: Saturday
A20: 19 | B20: 46047 | C20: Deonarayan Jayanti | D20: Sunday
A21: 20 | B21: 46048 | C21: Republic Day | D21: Monday | E21: =VLOOKUP(B21,'All ecxept A grades - 13 days'!B20:E214,4,0) -> Digi_National | F21: =VLOOKUP(C21,'All ecxept A grades - 13 days'!C20:F214,4,0) -> Digi_National | G21: Digi_National | H21: Digi_National | I21: Digi_National | J21: Digi_National | K21: Digi_National | L21: Digi_National | M21: Digi_National | N21: Digi_National | O21: Digi_National | P21: Digi_National | Q21: Digi_National | R21: Digi_National | S21: Digi_National | T21: Digi_National | U21: Digi_National | V21: Digi_National | W21: Digi_National | X21: Digi_National | Y21: Digi_National | Z21: Digi_National | AA21: Digi_National | AB21: Digi_National | AC21: =VLOOKUP(B21,'All ecxept A grades - 13 days'!B20:AC214,28,0) -> Digi_National | AD21: Digi_National | AE21: Digi_National | AF21: Digi_National | AG21: Digi_National | AH21: =VLOOKUP(B21,'All ecxept A grades - 13 days'!B20:AH214,33,0) -> Digi_National | AI21: Digi_National | AJ21: Digi_National | AK21: Digi_National
A22: 21 | B22: 46049 | C22: Gwthar Bathou San (Assam-specific)/Sri Madvanavami | D22: Tuesday
A23: 22 | B23: 46051 | C23: Guru Gobind Singh Jayanti /Saraswati Puja | D23: Thursday
A24: 23 | B24: 46053 | C24: Me-Dam-Me-Phi / Vishwakarma Jayanti | D24: Saturday
A25: 24 | B25: 46054 | C25: Sant Ravidas Jayanthi Basant Panchami | D25: Sunday
A26: 25 | B26: 46056 | C26: Shab-e-Barat | D26: Tuesday
A27: 26 | B27: 46057 | C27: Shab-e-Barath | D27: Wednesday
A28: 27 | B28: 46065 | C28: Maharshi Dayanand Saraswati Jayanti | D28: Thursday
A29: 28 | B29: 46068 | C29: Mahasivarathri | D29: Sunday
A30: 29 | B30: 46069 | C30: Mahashivrathri / Mela Dosmoche | D30: Monday
A31: 30 | B31: 46071 | C31: Losar (Tibetan New Year) | D31: Wednesday | AA31: Digi_Festival
A32: 31 | B32: 46072 | C32: Guru Rinpoche Day (commonly given in Leh) / Chhatrapati Shivaji Maharaj Jayanti | D32: Thursday
A33: 32 | B33: 46073 | C33: State Day | D33: Friday | U33: Digi_National | Y33: Digi_Festival
A34: 33 | B34: 46079 | C34: Akhil Sikkim Khas Chettri Bahun Kalyan Sangh's Foundation Day | D34: Thursday
A35: 34 | B35: 46083 | C35: Holi ka dahan / Ramzan | D35: Monday
A36: 35 | B36: 46084 | C36: Holi / Tangpe Chongya | D36: Tuesday | L36: Digi_Festival | Q36: Digi_Festival | T36: Digi_Festival | V36: Digi_Festival | W36: Digi_Festival | AA36: Digi_Festival | AC36: =VLOOKUP(B36,'All ecxept A grades - 13 days'!B35:AC229,28,0) -> Digi_Festival
A37: 36 | B37: 46085 | C37: Holi | D37: Wednesday | E37: =VLOOKUP(B37,'All ecxept A grades - 13 days'!B36:E230,4,0) -> Digi_Festival | F37: =VLOOKUP(C37,'All ecxept A grades - 13 days'!C36:F230,4,0) -> Digi_Festival | G37: Digi_Festival | H37: Digi_Festival | I37: Digi_Festival | K37: Digi_Festival | M37: Digi_Festival | N37: Digi_Festival | O37: Digi_Festival | P37: Digi_Festival | R37: Digi_Festival | S37: Digi_Festival | U37: Digi_Festival | X37: Digi_Festival | Y37: Digi_Festival | Z37: Digi_Festival | AB37: Digi_Festival | AJ37: Digi_Festival | AK37: Digi_Festival
A38: 37 | B38: 46086 | C38: Bhai-Dooj (Holi) | D38: Thursday
A39: 38 | B39: 46091 | C39: Shahadat Hzt Ali (R.A.) | D39: Tuesday
A40: 39 | B40: 46092 | C40: Sahahdat-e- hazrat Ali | D40: Wednesday
...

Sheet For Senior grades- 13 days (2)
A1: Sl.no. | B1: Date | C1: Festival | D1: Day | E1: Delhi | F1: Chandigarh | G1: Haryana | H1: Himachal Pradesh | I1: Jammu & Kashmir | J1: Ladakh | K1: Punjab | L1: Rajasthan | M1: Uttarakhand | N1: Uttar Pradesh | O1: Chhattisgarh | P1: Madhya Pradesh | Q1: Bihar | R1: Jharkhand | S1: Odisha | T1: West Bengal | U1: Arunachal Pradesh | V1: Assam | W1: Manipur | X1: Meghalaya | Y1: Mizoram | Z1: Nagaland | AA1: Sikkim | AB1: Tripura | AC1: Andhra Pradesh | AD1: Karnataka | AE1: Kerala | AF1: Puducherry | AG1: Tamil Nadu | AH1: Telangana | AI1: Goa | AJ1: Gujarat | AK1: Maharashtra | XDX1: Yes
A2: 1 | B2: 46023 | C2: New Year’s Day | D2: Thursday | H2: Optional | N2: Regional | O2: Regional | Q2: Optional | T2: Regional | W2: Regional | X2: Optional | Y2: Optional | AA2: Optional | AD2: Regional | AE2: Optional | AF2: Regional | AG2: Optional | AI2: Optional | AJ2: =VLOOKUP(B2,'For A grades - 11 days'!B1:AJ187,35,0) -> Optional
A3: 2 | B3: 46024 | C3: Mannam Jayanthi | D3: Friday | Y3: Regional
A4: 3 | B4: 46025 | C4: Maa Shakambhari Jayanti & Cherchera / Birthday of Hazarat Ali / Savitribai Phule Jayanti | D4: Saturday | J4: Optional-WE | N4: Regional-WE | O4: Regional-WE
A5: 4 | B5: 46027 | C5: Guru Gobind Singh Jayanti / Losar (Tibetan New Year) | D5: Tuesday | J5: Optional | N5: Regional
A6: 5 | B6: 46029 | C6: Naga Army Day /Rajim Bhaktin Mata Jayanti | D6: Wednesday | O6: Regional
B7: 46031 | C7: Death Anniversary of (L) Maharaja Gambhir Singh | D7: Friday | W7: Regional
A8: 6 | B8: 46032 | C8: World Hindi Day | D8: Saturday | O8: Regional-WE
A9: 7 | B9: 46033 | C9: Missionary Day | D9: Sunday | Y9: Optional-WE
A10: 8 | B10: 46034 | C10: Birthday of Swami Vivekananda | D10: Monday | T10: Regional
A11: 9 | B11: 46035 | C11: Lohri | D11: Tuesday | J11: Optional
A12: 10 | B12: 46036 | C12: Pongal / Makar Sankranti/Magh Bihu & Tusu Puja | D12: Wednesday | H12: Optional | N12: Regional | O12: Regional | Q12: Regional | S12: Regional | V12: Regional | AJ12: =VLOOKUP(B12,'For A grades - 11 days'!B11:AJ200,35,0) -> Regional
A13: 11 | B13: 46037 | C13: Uttarayana Punyakala, Makara Sankranti Festival/Pongal | D13: Thursday | V13: Regional | AA13: Regional | AD13: Regional | AE13: Regional | AF13: Regional | AG13: Regional | AJ13: =VLOOKUP(B13,'For A grades - 11 days'!B12:AJ201,35,0) -> Optional
A14: 12 | B14: 46038 | C14: Thiruvalluvar Day / Mattu Pongal / Kanuma (AP only) | D14: Friday | AE14: Regional | AF14: Regional | AG14: Regional
A15: 13 | B15: 46039 | C15: Uzhavar Thirunal | D15: Saturday | J15: Optional-WE | AE15: Regional-WE | AG15: Regional-WE
A16: 14 | B16: 46041 | C16: Sonam Lhosar / Sonam Lhochhar | D16: Monday | AA16: Optional
A17: 15 | B17: 46042 | C17: Shaheed Gaindsingh Shahadat Diwas | D17: Tuesday | O17: Regional
A18: 16 | B18: 46045 | C18: Basanta Panchami / Netaji Subhas Chandra Bose’s Birthday | D18: Friday | H18: Optional | N18: Regional | O18: Regional | Q18: Regional | S18: Regional | T18: Regional | V18: Regional
A19: 17 | B19: 46046 | C19: Karpoori Thakur Jayanti | D19: Saturday | N19: Regional-WE | Q19: Regional-WE
A20: 18 | B20: 46047 | C20: Deonarayan Jayanti / Statehood Day | D20: Sunday | H20: Regional-WE | L20: Regional-WE
A21: 19 | B21: 46048 | C21: Republic Day | D21: Monday | H21: National | J21: National | L21: National | N21: National | O21: National | Q21: National | S21: National | T21: National | V21: National | W21: National | X21: National | Y21: National | AA21: National | AD21: National | AE21: National | AF21: National | AG21: National | AI21: National | AJ21: =VLOOKUP(B21,'For A grades - 11 days'!B20:AJ209,35,0) -> National
A22: 20 | B22: 46049 | C22: Gwthar Bathou San (Assam-specific)/Sri Madvanavami | D22: Tuesday | V22: Regional | AD22: Regional
A23: 21 | B23: 46051 | C23: Guru Gobind Singh Jayanti /Saraswati Puja | D23: Thursday
A24: 22 | B24: 46053 | C24: Me-Dam-Me-Phi | D24: Saturday | V24: Regional-WE | AJ24: =VLOOKUP(B24,'For A grades - 11 days'!B23:AJ212,35,0) -> Optional-WE
A25: 23 | B25: 46054 | C25: Sant Ravidas Jayanthi | D25: Sunday | H25: Regional-WE | N25: Regional-WE | Q25: Regional-WE | V25: Regional-WE | AE25: Regional-WE | AG25: Regional-WE
A26: 24 | B26: 46056 | C26: Shab-e-Barat | D26: Tuesday | O26: Regional
A27: 25 | B27: 46057 | C27: Shab-e-Barath | D27: Wednesday | N27: Regional | Q27: Regional | AD27: Regional | AJ27: =VLOOKUP(B27,'For A grades - 11 days'!B26:AJ215,35,0) -> Optional
A28: 26 | B28: 46065 | C28: Maharshi Dayanand Saraswati Jayanti | D28: Thursday | H28: Optional | O28: Regional
A29: 27 | B29: 46068 | C29: Mahasivarathri | D29: Sunday | H29: Regional-WE | J29: Optional-WE | L29: Regional-WE | N29: Regional-WE | S29: Regional-WE | T29: Regional-WE | W29: Regional-WE | AI29: Regional-WE | AJ29: =VLOOKUP(B29,'For A grades - 11 days'!B28:AJ217,35,0) -> Regional-WE
A30: 28 | B30: 46069 | C30: Mahashivrathri / Mela Dosmoche | D30: Monday | J30: Optional | Q30: Regional
A31: 29 | B31: 46071 | C31: Losar (Tibetan New Year) | D31: Wednesday | AA31: Regional
A32: 30 | B32: 46072 | C32: Guru Rinpoche Day (commonly given in Leh) / Chhatrapati Shivaji Maharaj Jayanti | D32: Thursday | O32: Regional
A33: 31 | B33: 46073 | C33: State Day | D33: Friday | Y33: Regional
A34: 32 | B34: 46079 | C34: Akhil Sikkim Khas Chettri Bahun Kalyan Sangh's Foundation Day | D34: Thursday | AA34: Regional
A35: 33 | B35: 46083 | C35: Holi ka dahan / Ramzan | D35: Monday | L35: Regional | N35: Regional | Q35: Regional | AD35: Regional
A36: 34 | B36: 46084 | C36: Holi / Tangpe Chongya | D36: Tuesday | J36: Optional | L36: Regional | O36: Regional | Q36: Regional | T36: Regional | V36: Regional | W36: Regional | AA36: Regional | AI36: Regional | AJ36: =VLOOKUP(B36,'For A grades - 11 days'!B35:AJ224,35,0) -> Optional
A37: 35 | B37: 46085 | C37: Holi | D37: Wednesday | H37: Regional | J37: Regional | N37: Regional | O37: Regional | S37: Regional | W37: Regional | X37: Regional | Y37: Regional | AJ37: =VLOOKUP(B37,'For A grades - 11 days'!B36:AJ225,35,0) -> Regional
A38: 36 | B38: 46086 | C38: Bhai-Dooj (Holi) | D38: Thursday | N38: Regional | O38: Regional
A39: 37 | B39: 46092 | C39: Sahahdat-e- hazrat Ali | D39: Wednesday | AJ39: =VLOOKUP(B39,'For A grades - 11 days'!B38:AJ227,35,0) -> Optional
A40: 38 | B40: 46094 | C40: Chapchar Kut | D40: Friday | J40: Optional | N40: Regional | Y40: Regional
...

Sheet Conneqt Business Solutions
A1: - | B1: - | C1: - | D1: - | E1: 2026 | H1: North India | R1: Central India | T1: East India | X1: Northeast India | AF1: South India | AL1: West India
A2: S.no | B2: Date | C2: Festival | D2: Day | E2: Date | F2: Festival | G2: Day | H2: Delhi | I2: Chandigarh | J2: Haryana | K2: Himachal Pradesh | L2: Jammu & Kashmir | M2: Ladakh | N2: Punjab | O2: Rajasthan | P2: Uttarakhand | Q2: Uttar Pradesh | R2: Chhattisgarh | S2: Madhya Pradesh | T2: Bihar | U2: Jharkhand | V2: Odisha | W2: West Bengal | X2: Arunachal Pradesh | Y2: Assam | Z2: Manipur | AA2: Meghalaya | AB2: Mizoram | AC2: Nagaland | AD2: Sikkim | AE2: Tripura | AF2: Andhra Pradesh | AG2: Karnataka | AH2: Kerala | AI2: Puducherry | AJ2: Tamil Nadu | AK2: Telangana | AL2: Goa | AM2: Gujarat | AN2: Maharashtra | XEA2: Yes
A3: 1 | B3: 45658 | C3: New Year's Day | D3: =TEXT(B3,"ddddddd") -> Wednesday
A4: 2 | B4: 45671 | C4: Pongal/Makara Sankranti Festival Uttarayana Punyakala | D4: =TEXT(B4,"ddddddd") -> Tuesday
A5: 3 | B5: 45672 | C5: Pongal/Sankranti/ Thiruvalluvar Day/ Magh Bihu | D5: =TEXT(B5,"ddddddd") -> Wednesday
A6: 4 | B6: 45683 | C6: Republic Day | D6: =TEXT(B6,"ddddddd") -> Sunday
A7: 5 | B7: 45714 | C7: Maha Shivratri | D7: =TEXT(B7,"ddddddd") -> Wednesday
A8: 6 | B8: 45730 | C8: Holi/Dhulandi/Yaosang | D8: =TEXT(B8,"ddddddd") -> Friday
A9: 7 | B9: 45731 | C9: Holi/Dhulandi/Yaosang | D9: =TEXT(B9,"ddddddd") -> Saturday
A10: 8 | B10: 45746 | C10: Ugadi/ Gudi Padava/ Telugu New Year | D10: =TEXT(B10,"ddddddd") -> Sunday
A11: 9 | B11: 45747 | C11: Ramzan Id/Eid-ul-Fitar/ Idul Fitr | D11: =TEXT(B11,"ddddddd") -> Monday
A12: 10 | B12: 45748 | C12: Ramzan Id/Eid-ul-Fitar/ Idul Fitr | D12: =TEXT(B12,"ddddddd") -> Tuesday
A13: 11 | B13: 45757 | C13: Mahavir Jayanti | D13: =TEXT(B13,"ddddddd") -> Thursday
A14: 12 | B14: 45761 | C14: Dr Ambedkar Jayanti/ Tamil New Year Day/ Mahavir Jayanti/Vaisakhi/Cheiraoba/Bengali New Year/Bohag Bihu | D14: =TEXT(B14,"ddddddd") -> Monday
... A40: 38 | B40: 46016 | C40: Christmas Day | D40: =TEXT(B40,"ddddddd") -> Thursday
A43: Total
D44: Sunday
D45: Saturday

Sheet Conneqt Digital
A1: - | C1: - | D1: - | E1: - | F1: South | L1: East | U1: West | Z1: North
A2: S.no | B2: S.no | C2: Date | D2: Festival | E2: Day | F2: Telangana | G2: Andhra Pradesh | H2: Kerala | I2: Karnataka | J2: Tamil Nadu | K2: Pondicherry | L2: Jharkhand | M2: Arunachal Pradesh | N2: Manipur | O2: Meghalaya | P2: Assam | Q2: Bihar | R2: Odisha | S2: Tripura | T2: West Bengal | U2: Chhattisgarh | V2: Goa | W2: Madhya Pradesh | X2: Gujarat | Y2: Maharashtra | Z2: Delhi | AA2: Haryana | AB2: Chandigarh | AC2: Himachal Pradesh | AD2: Jammu and Kashmir | AE2: Punjab | AF2: Rajasthan | AG2: Uttar Pradesh | AH2: Uttarakhand | AL2: Proposed | AO2: g
A3: 1 | B3: 1 | C3: 45658 | D3: New Year's Day | E3: =TEXT(C3,"ddddddd") -> Wednesday | F3: Yes | G3: Yes | H3: Yes | I3: Yes | J3: Yes | K3: Yes | L3: Yes | M3: Yes | N3: Yes | O3: Yes | P3: Yes | Q3: Yes | R3: Yes | S3: Yes | T3: Yes | U3: Yes | V3: Yes | W3: Yes | X3: Yes | Y3: Yes | Z3: Yes | AA3: Yes | AB3: Yes | AC3: Yes | AD3: Yes | AE3: Yes | AF3: Yes | AG3: Yes | AH3: Yes | AI3: =COUNTA(F3:AH3) -> 29 | AK3: YES | AL3: YES | AN3: =VLOOKUP(D3,'Conneqt Business Solutions'!C3:C40,1,0) -> New Year's Day | AO3: =AN3=D3 -> TRUE
A4: 2 | B4: 2 | C4: 45671 | D4: Pongal/Makara Sankranti Festival Uttarayana Punyakala | E4: =TEXT(C4,"ddddddd") -> Tuesday | F4: Yes | I4: Yes | J4: Yes | K4: Yes | M4: Yes | R4: Yes | X4: Yes | AC4: Yes | AG4: Yes | AH4: Yes | AI4: =COUNTA(F4:AH4) -> 10 | AN4: =VLOOKUP(D4,'Conneqt Business Solutions'!C4:C41,1,0) -> Pongal/Makara Sankranti Festival Uttarayana Punyakala | AO4: =AN4=D4 -> TRUE
A5: 3 | B5: 3 | C5: 45672 | D5: Pongal/Sankranti/ Thiruvalluvar Day/ Magh Bihu | E5: =TEXT(C5,"ddddddd") -> Wednesday | G5: Yes | P5: Yes | Q5: Yes | AI5: =COUNTA(F5:AH5) -> 3 | AN5: =VLOOKUP(D5,'Conneqt Business Solutions'!C5:C42,1,0) -> Pongal/Sankranti/ Thiruvalluvar Day/ Magh Bihu | AO5: =AN5=D5 -> TRUE
A6: 4 | B6: 4 | C6: 45683 | D6: Republic Day | E6: =TEXT(C6,"ddddddd") -> Sunday | F6: Yes | G6: Yes | H6: Yes | I6: Yes | J6: Yes | K6: Yes | L6: Yes | M6: Yes | N6: Yes | O6: Yes | P6: Yes | Q6: Yes | R6: Yes | S6: Yes | T6: Yes | U6: Yes | V6: Yes | W6: Yes | X6: Yes | Y6: Yes | Z6: Yes | AA6: Yes | AB6: Yes | AC6: Yes | AD6: Yes | AE6: Yes | AF6: Yes | AG6: Yes | AH6: Yes | AI6: =COUNTA(F6:AH6) -> 29 | AK6: YES | AL6: YES | AN6: =VLOOKUP(D6,'Conneqt Business Solutions'!C6:C43,1,0) -> Republic Day | AO6: =AN6=D6 -> TRUE
A7: 5 | B7: 5 | C7: 45714 | D7: Maha Shivratri | E7: =TEXT(C7,"ddddddd") -> Wednesday | W7: Yes | Z7: Yes | AD7: Yes | AF7: Yes | AI7: =COUNTA(F7:AH7) -> 4 | AN7: =VLOOKUP(D7,'Conneqt Business Solutions'!C7:C44,1,0) -> Maha Shivratri | AO7: =AN7=D7 -> TRUE
A8: 6 | B8: 6 | C8: 45730 | D8: Holi/Dhulandi/Yaosang | E8: =TEXT(C8,"ddddddd") -> Friday | L8: Yes | M8: Yes | N8: Yes | O8: Yes | P8: Yes | Q8: Yes | R8: Yes | S8: Yes | U8: Yes | V8: Yes | W8: Yes | X8: Yes | Y8: Yes | Z8: Yes | AA8: Yes | AB8: Yes | AC8: Yes | AD8: Yes | AE8: Yes | AF8: Yes | AG8: Yes | AH8: Yes | AI8: =COUNTA(F8:AH8) -> 22 | AK8: YES | AL8: YES | AN8: =VLOOKUP(D8,'Conneqt Business Solutions'!C8:C45,1,0) -> Holi/Dhulandi/Yaosang | AO8: =AN8=D8 -> TRUE
A9: 7 | B9: 7 | C9: 45731 | D9: Holi/Dhulandi/Yaosang | E9: =TEXT(C9,"ddddddd") -> Saturday | AI9: =COUNTA(F9:AH9) -> 0 | AN9: =VLOOKUP(D9,'Conneqt Business Solutions'!C9:C46,1,0) -> Holi/Dhulandi/Yaosang | AO9: =AN9=D9 -> TRUE
A10: 8 | B10: 8 | C10: 45746 | D10: Ugadi/ Gudi Padava/ Telugu New Year | E10: =TEXT(C10,"ddddddd") -> Sunday | AI10: =COUNTA(F10:AH10) -> 0 | AN10: =VLOOKUP(D10,'Conneqt Business Solutions'!C10:C47,1,0) -> Ugadi/ Gudi Padava/ Telugu New Year | AO10: =AN10=D10 -> TRUE
A11: 9 | B11: 9 | C11: 45747 | D11: Ramzan Id/Eid-ul-Fitar/ Idul Fitr | E11: =TEXT(C11,"ddddddd") -> Monday | AI11: =COUNTA(F11:AH11) -> 0 | AJ11: remove | AN11: =VLOOKUP(D11,'Conneqt Business Solutions'!C11:C48,1,0) -> Ramzan Id/Eid-ul-Fitar/ Idul Fitr | AO11: =AN11=D11 -> TRUE
A12: 10 | B12: 10 | C12: 45748 | D12: Ramzan Id/Eid-ul-Fitar/ Idul Fitr | E12: =TEXT(C12,"ddddddd") -> Tuesday | F12: Yes | G12: Yes | H12: Yes | I12: Yes | J12: Yes | K12: Yes | L12: Yes | M12: Yes | N12: Yes | O12: Yes | P12: Yes | Q12: Yes | R12: Yes | S12: Yes | T12: Yes | U12: Yes | V12: Yes | W12: Yes | X12: Yes | Y12: Yes | Z12: Yes | AA12: Yes | AB12: Yes | AC12: Yes | AD12: Yes | AE12: Yes | AF12: Yes | AG12: Yes | AH12: Yes | AI12: =COUNTA(F12:AH12) -> 29 | AJ12: All | AK12: YES | AL12: YES | AN12: =VLOOKUP(D12,'Conneqt Business Solutions'!C12:C49,1,0) -> Ramzan Id/Eid-ul-Fitar/ Idul Fitr | AO12: =AN12=D12 -> TRUE
A13: 11 | B13: 11 | C13: 45757 | D13: Mahavir Jayanti | E13: =TEXT(C13,"ddddddd") -> Thursday | AI13: =COUNTA(F13:AH13) -> 0 | AN13: =VLOOKUP(D13,'Conneqt Business Solutions'!C13:C50,1,0) -> Mahavir Jayanti | AO13: =AN13=D13 -> TRUE
A14: 12 | B14: 12 | C14: 45761 | D14: Dr Ambedkar Jayanti/ Tamil New Year Day/ Mahavir Jayanti/Vaisakhi/Cheiraoba/Bengali New Year/Bohag Bihu | E14: =TEXT(C14,"ddddddd") -> Monday | F14: Yes | G14: Yes | H14: Yes | I14: Yes | J14: Yes | K14: Yes | L14: Yes | N14: Yes | O14: Yes | P14: Yes | R14: Yes | S14: Yes | U14: Yes | Y14: Yes | AA14: Yes | AB14: Yes | AD14: Yes | AE14: Yes | AF14: Yes | AI14: =COUNTA(F14:AH14) -> 19 | AK14: YES | AL14: YES | AN14: =VLOOKUP(D14,'Conneqt Business Solutions'!C14:C51,1,0) -> Dr Ambedkar Jayanti/ Tamil New Year Day/ Mahavir Jayanti/Vaisakhi/Cheiraoba/Bengali New Year/Bohag Bihu | AO14: =AN14=D14 -> TRUE
A15: 13 | B15: 13 | C15: 45762 | D15: Bohag Bihu/Bengali New year/ Himachal Day | E15: =TEXT(C15,"ddddddd") -> Tuesday | M15: Yes | T15: Yes | AC15: Yes | AI15: =COUNTA(F15:AH15) -> 3 | AN15: =VLOOKUP(D15,'Conneqt Business Solutions'!C15:C52,1,0) -> Bohag Bihu/Bengali New year/ Himachal Day | AO15: =AN15=D15 -> TRUE
A16: 14 | B16: 14 | C16: 45765 | D16: Good Friday | E16: =TEXT(C16,"ddddddd") -> Friday | V16: Yes | AI16: =COUNTA(F16:AH16) -> 1 | AN16: =VLOOKUP(D16,'Conneqt Business Solutions'!C16:C53,1,0) -> Good Friday | AO16: =AN16=D16 -> TRUE
B17: 15 | C17: 45778 | D17: May Day/Gujarat/Maharastra Day | E17: =TEXT(C17,"ddddddd") -> Thursday | F17: Yes | G17: Yes | H17: Yes | I17: Yes | J17: Yes | K17: Yes | L17: Yes | M17: Yes | N17: Yes | O17: Yes | P17: Yes | Q17: Yes | R17: Yes | S17: Yes | T17: Yes | U17: Yes | V17: Yes | W17: Yes | X17: Yes | Y17: Yes | Z17: Yes | AA17: Yes | AB17: Yes | AC17: Yes | AD17: Yes | AE17: Yes | AF17: Yes | AG17: Yes | AH17: Yes | AI17: =COUNTA(F17:AH17) -> 29 | AJ17: All | AK17: YES | AL17: YES | AN17: =VLOOKUP(D17,'Conneqt Business Solutions'!C17:C54,1,0) -> May Day/Gujarat/Maharastra Day | AO17: =AN17=D17 -> TRUE
A18: 16 | B18: 16 | C18: 45789 | D18: Buddha Purnima | E18: =TEXT(C18,"ddddddd") -> Monday | S18: Yes | T18: Yes | U18: Yes | W18: Yes | Z18: Yes | AI18: =COUNTA(F18:AH18) -> 5 | AN18: =VLOOKUP(D18,'Conneqt Business Solutions'!C18:C55,1,0) -> Buddha Purnima | AO18: =AN18=D18 -> TRUE
A19: 17 | B19: 17 | C19: 45814 | D19: Muharram/Ashura (Tentative Date)/d-ul-Ad’ha (Bakrid)* | E19: =TEXT(C19,"ddddddd") -> Friday | AI19: =COUNTA(F19:AH19) -> 0 | AN19: =VLOOKUP(D19,'Conneqt Business Solutions'!C19:C56,1,0) -> Muharram/Ashura (Tentative Date)/d-ul-Ad’ha (Bakrid)* | AO19: =AN19=D19 -> TRUE
A20: 18 | B20: 18 | C20: 45815 | D20: Muharram/Ashura (Tentative Date)/d-ul-Ad’ha (Bakrid)* /Iduljuha | E20: =TEXT(C20,"ddddddd") -> Saturday | F20: Yes | G20: Yes | H20: Yes | J20: Yes | L20: Yes | M20: Yes | N20: Yes | O20: Yes | P20: Yes | Q20: Yes | R20: Yes | S20: Yes | T20: Yes | U20: Yes | V20: Yes | W20: Yes | Z20: Yes | AA20: Yes | AB20: Yes | AC20: Yes | AD20: Yes | AE20: Yes | AF20: Yes | AG20: Yes | AH20: Yes | AI20: =COUNTA(F20:AH20) -> 25 | AN20: =VLOOKUP(D20,'Conneqt Business Solutions'!C20:C57,1,0) -> Muharram/Ashura (Tentative Date)/d-ul-Ad’ha (Bakrid)* /Iduljuha | AO20: =AN20=D20 -> TRUE
B21: 19 | C21: 45835 | D21: Rath Yatra | E21: =TEXT(C21,"ddddddd") -> Friday | AI21: =COUNTA(F21:AH21) -> 0 | AN21: =VLOOKUP(D21,'Conneqt Business Solutions'!C21:C58,1,0) -> Rath Yatra | AO21: =AN21=D21 -> TRUE
A22: 19 | B22: 20 | C22: 45878 | D22: Raksha Bandhan | E22: =TEXT(C22,"ddddddd") -> Saturday | X22: Yes | AI22: =COUNTA(F22:AH22) -> 1 | AN22: =VLOOKUP(D22,'Conneqt Business Solutions'!C22:C59,1,0) -> Raksha Bandhan | AO22: =AN22=D22 -> TRUE
A23: 20 | B23: 21 | C23: 45882 | D23: Patriots Day | E23: =TEXT(C23,"ddddddd") -> Wednesday | N23: Yes | AI23: =COUNTA(F23:AH23) -> 1 | AL23: YES | AN23: =VLOOKUP(D23,'Conneqt Business Solutions'!C23:C60,1,0) -> Patriots Day | AO23: =AN23=D23 -> TRUE
A24: 21 | B24: 22 | C24: 45884 | D24: Independence Day | E24: =TEXT(C24,"ddddddd") -> Friday | F24: Yes | G24: Yes | H24: Yes | I24: Yes | J24: Yes | K24: Yes | L24: Yes | M24: Yes | N24: Yes | O24: Yes | P24: Yes | Q24: Yes | R24: Yes | S24: Yes | T24: Yes | U24: Yes | V24: Yes | W24: Yes | X24: Yes | Y24: Yes | Z24: Yes | AA24: Yes | AB24: Yes | AC24: Yes | AD24: Yes | AE24: Yes | AF24: Yes | AG24: Yes | AH24: Yes | AI24: =COUNTA(F24:AH24) -> 29 | AK24: YES | AL24: YES | AN24: =VLOOKUP(D24,'Conneqt Business Solutions'!C24:C61,1,0) -> Independence Day | AO24: =AN24=D24 -> TRUE
A25: 22 | B25: 23 | C25: 45896 | D25: Ganesh Chaturthi/Vinayaka Chavithi/Samvatsari (Chaturthi Paksha) | E25: =TEXT(C25,"ddddddd") -> Wednesday | F25: Yes | G25: Yes | H25: Yes | I25: Yes | J25: Yes | K25: Yes | X25: Yes | Y25: Yes | AI25: =COUNTA(F25:AH25) -> 8 | AK25: YES | AN25: =VLOOKUP(D25,'Conneqt Business Solutions'!C25:C62,1,0) -> Ganesh Chaturthi/Vinayaka Chavithi/Samvatsari (Chaturthi Paksha) | AO25: =AN25=D25 -> TRUE
A26: 23 | B26: 24 | C26: 45897 | D26: Ganesh Chaturthi/Ayyankali Jayanthi | E26: =TEXT(C26,"ddddddd") -> Thursday | AI26: =COUNTA(F26:AH26) -> 0 | AN26: =VLOOKUP(D26,'Conneqt Business Solutions'!C26:C63,1,0) -> Ganesh Chaturthi/Ayyankali Jayanthi | AO26: =AN26=D26 -> TRUE
A27: 24 | B27: 25 | C27: 45904 | D27: First Onam | E27: =TEXT(C27,"ddddddd") -> Thursday | H27: Yes | AI27: =COUNTA(F27:AH27) -> 1 | AN27: =VLOOKUP(D27,'Conneqt Business Solutions'!C27:C64,1,0) -> First Onam | AO27: =AN27=D27 -> TRUE
A28: 25 | B28: 26 | C28: 45905 | D28: Thiruvonam/ Milad - i- sherif/Eid e Milad | E28: =TEXT(C28,"ddddddd") -> Friday | H28: Yes | Y28: Yes | AI28: =COUNTA(F28:AH28) -> 2 | AN28: =VLOOKUP(D28,'Conneqt Business Solutions'!C28:C65,1,0) -> Thiruvonam/ Milad - i- sherif/Eid e Milad | AO28: =AN28=D28 -> TRUE
B29: 27 | C29: 45930 | D29: Maha Ashtami | E29: =TEXT(C29,"ddddddd") -> Tuesday | AI29: =COUNTA(F29:AH29) -> 0 | AL29: YES | AN29: =VLOOKUP(D29,'Conneqt Business Solutions'!C29:C66,1,0) -> Maha Ashtami | AO29: =AN29=D29 -> TRUE
A30: 26 | B30: 28 | C30: 45931 | D30: Mahanavami/Navaratni endsMaha Navami/Ayutha Pooja | E30: =TEXT(C30,"ddddddd") -> Wednesday | O30: Yes | T30: Yes | AI30: =COUNTA(F30:AH30) -> 2 | AN30: =VLOOKUP(D30,'Conneqt Business Solutions'!C30:C67,1,0) -> Mahanavami/Navaratni endsMaha Navami/Ayutha Pooja | AO30: =AN30=D30 -> TRUE
A31: 27 | B31: 29 | C31: 45932 | D31: Mahatma Gandhi Jayanti/Vijaya Dasami/Dussehra/Durga Puja | E31: =TEXT(C31,"ddddddd") -> Thursday | F31: Yes | G31: Yes | H31: Yes | I31: Yes | J31: Yes | K31: Yes | L31: Yes | M31: Yes | N31: Yes | O31: Yes | P31: Yes | Q31: Yes | R31: Yes | S31: Yes | T31: Yes | U31: Yes | V31: Yes | W31: Yes | X31: Yes | Y31: Yes | Z31: Yes | AA31: Yes | AB31: Yes | AC31: Yes | AD31: Yes | AE31: Yes | AF31: Yes | AG31: Yes | AH31: Yes | AI31: =COUNTA(F31:AH31) -> 29 | AK31: YES | AL31: YES | AN31: =VLOOKUP(D31,'Conneqt Business Solutions'!C31:C68,1,0) -> Mahatma Gandhi Jayanti/Vijaya Dasami/Dussehra/Durga Puja | AO31: =AN31=D31 -> TRUE
A32: 28 | B32: 30 | C32: 45950 | D32: Diwali/Deepavali/Kali Puja | E32: =TEXT(C32,"ddddddd") -> Monday | AI32: =COUNTA(F32:AH32) -> 0 | AJ32: remove | AN32: =VLOOKUP(D32,'Conneqt Business Solutions'!C32:C69,1,0) -> Diwali/Deepavali/Kali Puja | AO32: =AN32=D32 -> TRUE
A33: 29 | B33: 31 | C33: 45951 | D33: Diwali/Deepavali/Kali Puja | E33: =TEXT(C33,"ddddddd") -> Tuesday | F33: Yes | G33: Yes | H33: Yes | I33: Yes | J33: Yes | K33: Yes | L33: Yes | M33: Yes | N33: Yes | O33: Yes | P33: Yes | Q33: Yes | R33: Yes | S33: Yes | T33: Yes | U33: Yes | V33: Yes | W33: Yes | X33: Yes | Y33: Yes | Z33: Yes | AA33: Yes | AB33: Yes | AC33: Yes | AD33: Yes | AE33: Yes | AF33: Yes | AG33: Yes | AH33: Yes | AI33: =COUNTA(F33:AH33) -> 29 | AJ33: All | AK33: YES | AN33: =VLOOKUP(D33,'Conneqt Business Solutions'!C33:C70,1,0) -> Diwali/Deepavali/Kali Puja | AO33: =AN33=D33 -> TRUE
